<?xml version="1.0" ?>
<sdf version="1.10">
    <world name="car_world">
        <physics name="1ms" type="ignored">
            <max_step_size>0.001</max_step_size>
            <real_time_factor>1.0</real_time_factor>
        </physics>
        <plugin
            filename="gz-sim-physics-system"
            name="gz::sim::systems::Physics">
        </plugin>
        <plugin
            filename="gz-sim-user-commands-system"
            name="gz::sim::systems::UserCommands">
        </plugin>
        <plugin
            filename="gz-sim-scene-broadcaster-system"
            name="gz::sim::systems::SceneBroadcaster">
        </plugin>

        <plugin filename="gz-sim-imu-system"
                name="gz::sim::systems::Imu">
        </plugin>

        <light type="directional" name="sun">
            <cast_shadows>true</cast_shadows>
            <pose>0 0 10 0 0 0</pose>
            <diffuse>0.8 0.8 0.8 1</diffuse>
            <specular>0.2 0.2 0.2 1</specular>
            <attenuation>
                <range>1000</range>
                <constant>0.9</constant>
                <linear>0.01</linear>
                <quadratic>0.001</quadratic>
            </attenuation>
            <direction>-0.5 0.1 -0.9</direction>
        </light>

        <model name="ground_plane">
            <static>true</static>
            <link name="link">
                <collision name="collision">
                <geometry>
                    <plane>
                    <normal>0 0 1</normal>
                    </plane>
                </geometry>
                </collision>
                <visual name="visual">
                <geometry>
                    <plane>
                    <normal>0 0 1</normal>
                    <size>100 100</size>
                    </plane>
                </geometry>
                <material>
                    <ambient>0.8 0.8 0.8 1</ambient>
                    <diffuse>0.8 0.8 0.8 1</diffuse>
                    <specular>0.8 0.8 0.8 1</specular>
                </material>
                </visual>
            </link>
        </model>
	<model name='vehicle_blue' canonical_link='chassis'>
	    <pose relative_to='world'>0 0 0 0 0 0</pose>
	    <link name='chassis'>
        	<pose relative_to='__model__'>0.5 0 0.4 0 0 0</pose>
    	    <inertial> <!--inertial properties of the link mass, inertia matix-->
        	<mass>1.14395</mass>
        	<inertia>
            		<ixx>0.095329</ixx>
            		<ixy>0</ixy>
            		<ixz>0</ixz>
            		<iyy>0.381317</iyy>
            		<iyz>0</iyz>
            		<izz>0.476646</izz>
        	</inertia>
    	    </inertial>
    	    <visual name='visual'>
        	<geometry>
            		<box>
                		<size>2.0 1.0 0.5</size>
            		</box>
        	</geometry>
        	<!--let's add color to our link-->
        	<material>
            		<ambient>0.0 0.0 1.0 1</ambient>
            		<diffuse>0.0 0.0 1.0 1</diffuse>
            		<specular>0.0 0.0 1.0 1</specular>
        	</material>
    	    </visual>
		    <collision name='collision'>
            		<geometry>
                		<box>
                    			<size>2.0 1.0 0.5</size>
                		</box>
            		</geometry>
        	</collision>
    	    </link>
            <link name='left_wheel'>
                <pose relative_to="chassis">-0.5 0.6 0 -1.5707 0 0</pose>
                <inertial>
                    <mass>1</mass>
                    <inertia>
                        <ixx>0.043333</ixx>
                        <ixy>0</ixy>
                        <ixz>0</ixz>
                        <iyy>0.043333</iyy>
                        <iyz>0</iyz>
                        <izz>0.08</izz>
                    </inertia>
                </inertial>
                <visual name='visual'>
                    <geometry>
                        <cylinder>
                            <radius>0.4</radius>
                            <length>0.2</length>
                        </cylinder>
                    </geometry>
                    <material>
                        <ambient>1.0 0.0 0.0 1</ambient>
                        <diffuse>1.0 0.0 0.0 1</diffuse>
                        <specular>1.0 0.0 0.0 1</specular>
                    </material>
                </visual>
            <collision name='collision'>
                    <geometry>
                        <cylinder>
                            <radius>0.4</radius>
                            <length>0.2</length>
                        </cylinder>
                    </geometry>
            </collision>

            <sensor name="imu_sensor" type="imu">
                <always_on>1</always_on>
                <update_rate>1</update_rate>
                <visualize>true</visualize>
                <topic>imu</topic>
            </sensor>
            </link>
            <!--The same as left wheel but with different position-->
            <link name='right_wheel'>
                <pose relative_to="chassis">-0.5 -0.6 0 -1.5707 0 0</pose> <!--angles are in radian-->
                <inertial>
                    <mass>1</mass>
                    <inertia>
                        <ixx>0.043333</ixx>
                        <ixy>0</ixy>
                        <ixz>0</ixz>
                        <iyy>0.043333</iyy>
                        <iyz>0</iyz>
                        <izz>0.08</izz>
                    </inertia>
                </inertial>
                <visual name='visual'>
                    <geometry>
                        <cylinder>
                            <radius>0.4</radius>
                            <length>0.2</length>
                        </cylinder>
                    </geometry>
                    <material>
                        <ambient>1.0 0.0 0.0 1</ambient>
                        <diffuse>1.0 0.0 0.0 1</diffuse>
                        <specular>1.0 0.0 0.0 1</specular>
                    </material>
                </visual>
                <collision name='collision'>
                    <geometry>
                        <cylinder>
                            <radius>0.4</radius>
                            <length>0.2</length>
                        </cylinder>
                    </geometry>
                </collision>
            </link>

            <frame name="caster_frame" attached_to='chassis'>
                <pose>0.8 0 -0.2 0 0 0</pose>
            </frame>

            <!--caster wheel-->
            <link name='caster'>
                <pose relative_to='caster_frame'/>
                <inertial>
                    <mass>1</mass>
                    <inertia>
                        <ixx>0.016</ixx>
                        <ixy>0</ixy>
                        <ixz>0</ixz>
                        <iyy>0.016</iyy>
                        <iyz>0</iyz>
                        <izz>0.016</izz>
                    </inertia>
                </inertial>
                <visual name='visual'>
                    <geometry>
                        <sphere>
                            <radius>0.2</radius>
                        </sphere>
                    </geometry>
                    <material>
                        <ambient>0.0 1 0.0 1</ambient>
                        <diffuse>0.0 1 0.0 1</diffuse>
                        <specular>0.0 1 0.0 1</specular>
                    </material>
                </visual>
                <collision name='collision'>
                    <geometry>
                        <sphere>
                            <radius>0.2</radius>
                        </sphere>
                    </geometry>
                </collision>
            </link>
            <joint name='left_wheel_joint' type='revolute'>
                <pose relative_to='left_wheel'/>
                <parent>chassis</parent>
                <child>left_wheel</child>
                <axis>
                    <xyz expressed_in='__model__'>0 1 0</xyz> <!--can be defined as any frame or even arbitrary frames-->
                    <limit>
                        <lower>-1.79769e+308</lower>    <!--negative infinity-->
                        <upper>1.79769e+308</upper>     <!--positive infinity-->
                    </limit>
                </axis>
            </joint>

            <joint name='right_wheel_joint' type='revolute'>
                <pose relative_to='right_wheel'/>
                <parent>chassis</parent>
                <child>right_wheel</child>
                <axis>
                    <xyz expressed_in='__model__'>0 1 0</xyz>
                    <limit>
                        <lower>-1.79769e+308</lower>    <!--negative infinity-->
                        <upper>1.79769e+308</upper>     <!--positive infinity-->
                    </limit>
                </axis>
            </joint>

            <joint name='caster_wheel' type='ball'>
                <parent>chassis</parent>
                <child>caster</child>
            </joint>
            <plugin
                filename="gz-sim-diff-drive-system"
                name="gz::sim::systems::DiffDrive">
                <left_joint>left_wheel_joint</left_joint>
                <right_joint>right_wheel_joint</right_joint>
                <wheel_separation>1.2</wheel_separation>
                <wheel_radius>0.4</wheel_radius>
                <odom_publish_frequency>1</odom_publish_frequency>
                <topic>cmd_vel</topic>
            </plugin>

            <!-- Moving Forward-->
            <plugin filename="gz-sim-triggered-publisher-system"
                    name="gz::sim::systems::TriggeredPublisher">
                <input type="gz.msgs.Int32" topic="/keyboard/keypress">
                    <match field="data">16777235</match>
                </input>
                <output type="gz.msgs.Twist" topic="/cmd_vel">
                    linear: {x: 0.5}, angular: {z: 0.0}
                </output>
            </plugin>

            <!-- Moving Backward-->
            <plugin filename="gz-sim-triggered-publisher-system"
                    name="gz::sim::systems::TriggeredPublisher">
                <input type="gz.msgs.Int32" topic="/keyboard/keypress">
                    <match field="data">16777237</match>
                </input>
                <output type="gz.msgs.Twist" topic="/cmd_vel">
                    linear: {x: -0.5}, angular: {z: 0.0}
                </output>
            </plugin>

            <!-- Moving left-->
            <plugin filename="gz-sim-triggered-publisher-system"
                    name="gz::sim::systems::TriggeredPublisher">
                <input type="gz.msgs.Int32" topic="/keyboard/keypress">
                    <match field="data">16777234</match>
                </input>
                <output type="gz.msgs.Twist" topic="/cmd_vel">
                    linear: {x: 0.0}, angular: {z: 0.5}
                </output>
            </plugin>

            <!-- Moving right-->
            <plugin filename="gz-sim-triggered-publisher-system"
                    name="gz::sim::systems::TriggeredPublisher">
                <input type="gz.msgs.Int32" topic="/keyboard/keypress">
                    <match field="data">16777236</match>
                </input>
                <output type="gz.msgs.Twist" topic="/cmd_vel">
                    linear: {x: 0.0}, angular: {z: -0.5}
                </output>
            </plugin>
	</model>
    <!-- Box Obstacle 1 -->
    <model name="obstacle_1">
        <static>true</static>
        <pose>3 2 0.5 0 0 0</pose> <!-- x y z roll pitch yaw -->
        <link name="link">
            <collision name="collision">
                <geometry>
                    <box>
                        <size>1 1 1</size> <!-- width, depth, height -->
                    </box>
                </geometry>
            </collision>
            <visual name="visual">
                <geometry>
                    <box>
                        <size>1 1 1</size>
                    </box>
                </geometry>
                <material>
                    <ambient>1 0 0 1</ambient>
                    <diffuse>1 0 0 1</diffuse>
                    <specular>0.5 0.5 0.5 1</specular>
                </material>
            </visual>
        </link>
    </model>

    <!-- Cylinder Obstacle 2 -->
    <model name="obstacle_2">
        <static>true</static>
        <pose>-2 -3 0.5 0 0 0</pose>
        <link name="link">
            <collision name="collision">
                <geometry>
                    <cylinder>
                        <radius>0.5</radius>
                        <length>1.0</length>
                    </cylinder>
                </geometry>
            </collision>
            <visual name="visual">
                <geometry>
                    <cylinder>
                        <radius>0.5</radius>
                        <length>1.0</length>
                    </cylinder>
                </geometry>
                <material>
                    <ambient>0 1 0 1</ambient>
                    <diffuse>0 1 0 1</diffuse>
                </material>
            </visual>
        </link>
    </model>
    <!-- Wall 1 -->
    <model name="wall_1">
        <static>true</static>
        <pose>6 0 1 0 0 0</pose>
        <link name="link">
            <collision name="collision">
                <geometry>
                    <box>
                        <size>0.3 8 2</size>
                    </box>
                </geometry>
            </collision>
            <visual name="visual">
                <geometry>
                    <box>
                        <size>0.3 8 2</size>
                    </box>
                </geometry>
                <material>
                    <ambient>0.4 0.4 0.4 1</ambient>
                    <diffuse>0.4 0.4 0.4 1</diffuse>
                    <specular>0.2 0.2 0.2 1</specular>
                </material>
            </visual>
        </link>
    </model>

    <!-- Wall 2 -->
    <model name="wall_2">
        <static>true</static>
        <pose>0 6 1 0 0 1.5708</pose>
        <link name="link">
            <collision name="collision">
                <geometry>
                    <box>
                        <size>0.3 8 2</size>
                    </box>
                </geometry>
            </collision>
            <visual name="visual">
                <geometry>
                    <box>
                        <size>0.3 8 2</size>
                    </box>
                </geometry>
                <material>
                    <ambient>0.4 0.4 0.4 1</ambient>
                    <diffuse>0.4 0.4 0.4 1</diffuse>
                    <specular>0.2 0.2 0.2 1</specular>
                </material>
            </visual>
        </link>
    </model>

    <!-- Wall 3 -->
    <model name="wall_3">
        <static>true</static>
        <pose>-4 -8 1 0 0 1.5708</pose>
        <link name="link">
            <collision name="collision">
                <geometry>
                    <box>
                        <size>0.6 11 3</size>
                    </box>
                </geometry>
            </collision>
            <visual name="visual">
                <geometry>
                    <box>
                        <size>0.6 11 3</size>
                    </box>
                </geometry>
                <material>
                    <ambient>0.76 0.22 0.22 1</ambient>
                    <diffuse>0.76 0.22 0.22 1</diffuse>
                    <specular>0.56 0.44 0.44 1</specular>
                </material>
            </visual>
        </link>
    </model>

    <!-- Obstacle 3 -->
    <model name="obstacle_3">
        <static>true</static>
        <pose>4 -1 0.5 0 0 0</pose>
        <link name="link">
            <collision name="collision">
                <geometry>
                    <box>
                        <size>1 2 1</size>
                    </box>
                </geometry>
            </collision>
            <visual name="visual">
                <geometry>
                    <box>
                        <size>1 2 1</size>
                    </box>
                </geometry>
                <material>
                    <ambient>0 0 1 1</ambient>
                    <diffuse>0 0 1 1</diffuse>
                </material>
            </visual>
        </link>
    </model>

    <!-- Obstacle 4 -->
    <model name="obstacle_4">
        <static>true</static>
        <pose>-4 2 0.75 0 0 0</pose>
        <link name="link">
            <collision name="collision">
                <geometry>
                    <box>
                        <size>1.5 1 1.5</size>
                    </box>
                </geometry>
            </collision>
            <visual name="visual">
                <geometry>
                    <box>
                        <size>1.5 1 1.5</size>
                    </box>
                </geometry>
                <material>
                    <ambient>1 1 0 1</ambient>
                    <diffuse>1 1 0 1</diffuse>
                </material>
            </visual>
        </link>
    </model>

    <!-- Obstacle 5 -->
    <model name="obstacle_5">
        <static>true</static>
        <pose>1 4 0.6 0 0 0</pose>
        <link name="link">
            <collision name="collision">
                <geometry>
                    <sphere>
                        <radius>0.6</radius>
                    </sphere>
                </geometry>
            </collision>
            <visual name="visual">
                <geometry>
                    <sphere>
                        <radius>0.6</radius>
                    </sphere>
                </geometry>
                <material>
                    <ambient>1 0 1 1</ambient>
                    <diffuse>1 0 1 1</diffuse>
                </material>
            </visual>
        </link>
    </model>

    <!-- Obstacle 6 -->
    <model name="obstacle_6">
        <static>true</static>
        <pose>-1 -5 0.5 0 0 0</pose>
        <link name="link">
            <collision name="collision">
                <geometry>
                    <cylinder>
                        <radius>0.5</radius>
                        <length>1.0</length>
                    </cylinder>
                </geometry>
            </collision>
            <visual name="visual">
                <geometry>
                    <cylinder>
                        <radius>0.5</radius>
                        <length>1.0</length>
                    </cylinder>
                </geometry>
                <material>
                    <ambient>0 1 1 1</ambient>
                    <diffuse>0 1 1 1</diffuse>
                </material>
            </visual>
        </link>
    </model>

    <!-- Obstacle 7 -->
    <model name="obstacle_7">
        <static>true</static>
        <pose>5 3 0.4 0 0 0</pose>
        <link name="link">
            <collision name="collision">
                <geometry>
                    <box>
                        <size>0.8 0.8 0.8</size>
                    </box>
                </geometry>
            </collision>
            <visual name="visual">
                <geometry>
                    <box>
                        <size>0.8 0.8 0.8</size>
                    </box>
                </geometry>
                <material>
                    <ambient>1 0.5 0 1</ambient>
                    <diffuse>1 0.5 0 1</diffuse>
                </material>
            </visual>
        </link>
    </model>
    </world>
</sdf>