<?xml version="1.0" ?>
<sdf version="1.10">
  <world name="room">
    <physics name="1ms" type="ignored">
      <max_step_size>0.001</max_step_size>
      <real_time_factor>1.0</real_time_factor>
    </physics>

    <plugin filename="gz-sim-physics-system" name="gz::sim::systems::Physics"/>
    <plugin filename="gz-sim-user-commands-system" name="gz::sim::systems::UserCommands"/>
    <plugin filename="gz-sim-scene-broadcaster-system" name="gz::sim::systems::SceneBroadcaster"/>
    <plugin filename="gz-sim-imu-system" name="gz::sim::systems::Imu"/>
    <plugin filename="gz-sim-sensors-system" name="gz::sim::systems::Sensors">
      <render_engine>ogre2</render_engine>
    </plugin>


    <light type="directional" name="sun">
      <cast_shadows>true</cast_shadows>
      <pose>0 0 10 0 0 0</pose>
      <diffuse>0.8 0.8 0.8 1</diffuse>
      <specular>0.2 0.2 0.2 1</specular>
      <attenuation>
        <range>1000</range>
        <constant>0.9</constant>
        <linear>0.01</linear>
        <quadratic>0.001</quadratic>
      </attenuation>
      <direction>-0.5 0.1 -0.9</direction>
    </light>

    <model name="ground_plane">
      <static>true</static>
      <link name="link">
        <collision name="collision">
          <geometry>
            <plane>
              <normal>0 0 1</normal>
            </plane>
          </geometry>
        </collision>
        <visual name="visual">
          <geometry>
            <plane>
              <normal>0 0 1</normal>
              <size>100 100</size>
            </plane>
          </geometry>
          <material>
            <ambient>0.8 0.8 0.8 1</ambient>
            <diffuse>0.8 0.8 0.8 1</diffuse>
            <specular>0.8 0.8 0.8 1</specular>
          </material>
        </visual>
      </link>
    </model>

    <!-- Include FLIP here when needed -->
    
    <model name='FLIP' canonical_link='chassis'>
      <pose>0 0 0 0 0 0</pose>

      <link name='chassis'>
        <pose relative_to='__model__'>0 0 0.625 0 0 0</pose>
        <inertial>
          <pose>0 0 0 0 0 0</pose>
          <mass>450.0</mass>
          <inertia>
            <ixx>62.438</ixx>
            <ixy>0</ixy>
            <ixz>0</ixz>
            <iyy>131.438</iyy>
            <iyz>0</iyz>
            <izz>111.188</izz>
          </inertia>
        </inertial>
        <visual name='visual'>
          <geometry><box><size>1.55 0.75 1.05</size></box></geometry>
          <material>
            <ambient>0.0 0.0 1.0 1</ambient>
            <diffuse>0.0 0.0 1.0 1</diffuse>
            <specular>0.0 0.0 1.0 1</specular>
          </material>
        </visual>
        <collision name='collision'>
          <geometry><box><size>1.55 0.75 1.05</size></box></geometry>
        </collision>
      </link>


      <!-- LiDAR link -->
      <link name='lidar_link'>
        <pose relative_to='chassis'>0.6 0 0.3 0 0 0</pose>
        <inertial>
          <mass>0.1</mass>
          <inertia>
            <ixx>0.000166</ixx><ixy>0</ixy><ixz>0</ixz>
            <iyy>0.000166</iyy><iyz>0</iyz>
            <izz>0.000166</izz>
          </inertia>
        </inertial>
        <visual name='visual'>
          <geometry><cylinder><radius>0.15</radius><length>0.08</length></cylinder></geometry>
          <material>
            <ambient>1 0.0 0.0 1</ambient>
            <diffuse>1.0 0.0 0.0 1</diffuse>
          </material>
        </visual>
        <collision name='collision'>
          <geometry><cylinder><radius>0.05</radius><length>0.08</length></cylinder></geometry>
        </collision>

        <sensor name="gpu_lidar" type="gpu_lidar">
          <pose>0 0 0 0 0 0</pose>  <!-- relative to lidar_link, now centered -->
          <always_on>1</always_on>
          <update_rate>20</update_rate>
          <lidar>
            <scan>
              <horizontal>
                <samples>320</samples><resolution>1</resolution>
                <min_angle>-3.14159</min_angle><max_angle>3.14159</max_angle>
              </horizontal>
              <vertical>
                <samples>64</samples><resolution>1</resolution>
                <min_angle>-0.610865</min_angle>
                <max_angle>0.610865</max_angle>
              </vertical>
            </scan>
            <range><min>0.08</min><max>10.0</max><resolution>0.01</resolution></range>
          </lidar>
          <visualize>true</visualize>
          <topic>lidar</topic>
        </sensor>
      </link>

      <!-- Fixed joint: chassis -> lidar_link -->
      <joint name="lidar_joint" type="fixed">
        <parent>chassis</parent>
        <child>lidar_link</child>
      </joint>


      <!-- IMU link -->
      <link name='imu_link'>
        <!-- Centered on chassis -->
        <pose relative_to='chassis'>0 0 0 0 0 0</pose>
        <inertial>
          <mass>0.01</mass>
          <inertia>
            <ixx>0.000001</ixx><ixy>0</ixy><ixz>0</ixz>
            <iyy>0.000001</iyy><iyz>0</iyz>
            <izz>0.000001</izz>
          </inertia>
        </inertial>

        <sensor name="imu_sensor" type="imu">
          <always_on>1</always_on>
          <update_rate>20</update_rate>
          <visualize>true</visualize>
          <topic>imu</topic>
        </sensor>
      </link>

      <!-- Fixed joint: chassis -> imu_link -->
      <joint name="imu_joint" type="fixed">
        <parent>chassis</parent>
        <child>imu_link</child>
      </joint>

      <link name='left_back_wheel'>
        <pose relative_to="chassis">-0.533 0.475 -0.383 -1.5707 0 0</pose>
        <inertial><mass>5</mass><inertia><ixx>0.694</ixx><ixy>0</ixy><ixz>0</ixz><iyy>1.460</iyy><iyz>0</iyz><izz>1.235</izz></inertia></inertial>
        <visual name='visual'><geometry><cylinder><radius>0.242</radius><length>0.2</length></cylinder></geometry></visual>
        <collision name='collision'><geometry><cylinder><radius>0.242</radius><length>0.2</length></cylinder></geometry></collision>
      </link>

      <link name='left_middle_wheel'>
        <pose relative_to="chassis">0 0.475 -0.383 -1.5707 0 0</pose>
        <inertial><mass>5</mass><inertia><ixx>0.694</ixx><ixy>0</ixy><ixz>0</ixz><iyy>1.460</iyy><iyz>0</iyz><izz>1.235</izz></inertia></inertial>
        <visual name='visual'><geometry><cylinder><radius>0.242</radius><length>0.2</length></cylinder></geometry></visual>
        <collision name='collision'><geometry><cylinder><radius>0.242</radius><length>0.2</length></cylinder></geometry></collision>
      </link>

      <link name='right_back_wheel'>
        <pose relative_to="chassis">-0.533 -0.475 -0.383 -1.5707 0 0</pose>
        <inertial><mass>5</mass><inertia><ixx>0.694</ixx><ixy>0</ixy><ixz>0</ixz><iyy>1.460</iyy><iyz>0</iyz><izz>1.235</izz></inertia></inertial>
        <visual name='visual'><geometry><cylinder><radius>0.242</radius><length>0.2</length></cylinder></geometry></visual>
        <collision name='collision'><geometry><cylinder><radius>0.242</radius><length>0.2</length></cylinder></geometry></collision>
      </link>

      <link name='right_middle_wheel'>
        <pose relative_to="chassis">0 -0.475 -0.383 -1.5707 0 0</pose>
        <inertial><mass>5</mass><inertia><ixx>0.694</ixx><ixy>0</ixy><ixz>0</ixz><iyy>1.460</iyy><iyz>0</iyz><izz>1.235</izz></inertia></inertial>
        <visual name='visual'><geometry><cylinder><radius>0.242</radius><length>0.2</length></cylinder></geometry></visual>
        <collision name='collision'><geometry><cylinder><radius>0.242</radius><length>0.2</length></cylinder></geometry></collision>
      </link>

      <link name='left_front_steer_link'>
        <pose relative_to="chassis">0.533 0.475 -0.383 0 0 0</pose>
        <inertial><mass>1.0</mass><inertia><ixx>0.01</ixx><ixy>0</ixy><ixz>0</ixz><iyy>0.01</iyy><iyz>0</iyz><izz>0.01</izz></inertia></inertial>
      </link>

      <link name='right_front_steer_link'>
        <pose relative_to="chassis">0.533 -0.475 -0.383 0 0 0</pose>
        <inertial><mass>1.0</mass><inertia><ixx>0.01</ixx><ixy>0</ixy><ixz>0</ixz><iyy>0.01</iyy><iyz>0</iyz><izz>0.01</izz></inertia></inertial>
      </link>

      <link name='left_front_wheel'>
        <pose relative_to="left_front_steer_link">0 0 0 -1.5707 0 0</pose>
        <inertial><mass>5</mass><inertia><ixx>0.694</ixx><ixy>0</ixy><ixz>0</ixz><iyy>1.460</iyy><iyz>0</iyz><izz>1.235</izz></inertia></inertial>
        <visual name='visual'>
          <geometry><cylinder><radius>0.242</radius><length>0.2</length></cylinder></geometry>
          <!-- <material><ambient>1.0 0.0 0.0 1</ambient><diffuse>1.0 0.0 0.0 1</diffuse><specular>1.0 0.0 0.0 1</specular></material> -->
        </visual>
        <collision name='collision'><geometry><cylinder><radius>0.242</radius><length>0.2</length></cylinder></geometry></collision>
      </link>

      <link name='right_front_wheel'>
        <pose relative_to="right_front_steer_link">0 0 0 -1.5707 0 0</pose>
        <inertial><mass>5</mass><inertia><ixx>0.694</ixx><ixy>0</ixy><ixz>0</ixz><iyy>1.460</iyy><iyz>0</iyz><izz>1.235</izz></inertia></inertial>
        <visual name='visual'>
          <geometry><cylinder><radius>0.242</radius><length>0.2</length></cylinder></geometry>
          <!-- <material><ambient>1.0 0.0 0.0 1</ambient><diffuse>1.0 0.0 0.0 1</diffuse><specular>1.0 0.0 0.0 1</specular></material> -->
        </visual>
        <collision name='collision'><geometry><cylinder><radius>0.242</radius><length>0.2</length></cylinder></geometry></collision>
      </link>



      <!-- Wheel joints -->
      <joint name="left_front_wheel_joint" type="revolute">
      <parent>chassis</parent>
      <child>left_front_wheel</child>
      <axis><xyz>0 0 1</xyz></axis>
      </joint>

      <joint name="left_middle_wheel_joint" type="revolute">
      <parent>chassis</parent>
      <child>left_middle_wheel</child>
      <axis><xyz>0 0 1</xyz></axis>
      </joint>

      <joint name="left_back_wheel_joint" type="revolute">
      <parent>chassis</parent>
      <child>left_back_wheel</child>
      <axis><xyz>0 0 1</xyz></axis>
      </joint>

      <joint name="right_front_wheel_joint" type="revolute">
      <parent>chassis</parent>
      <child>right_front_wheel</child>
      <axis><xyz>0 0 1</xyz></axis>
      </joint>

      <joint name="right_middle_wheel_joint" type="revolute">
      <parent>chassis</parent>
      <child>right_middle_wheel</child>
      <axis><xyz>0 0 1</xyz></axis>
      </joint>

      <joint name="right_back_wheel_joint" type="revolute">
      <parent>chassis</parent>
      <child>right_back_wheel</child>
      <axis><xyz>0 0 1</xyz></axis>
      </joint>


      <!-- Diff Drive Plugin -->
      <plugin
      filename="gz-sim-diff-drive-system"
      name="gz::sim::systems::DiffDrive">

      <!-- all 6 wheels driven -->
      <left_joint>left_back_wheel_joint</left_joint>
      <left_joint>left_middle_wheel_joint</left_joint>
      <left_joint>left_front_wheel_joint</left_joint>

      <right_joint>right_back_wheel_joint</right_joint>
      <right_joint>right_middle_wheel_joint</right_joint>
      <right_joint>right_front_wheel_joint</right_joint>

      <wheel_separation>0.95</wheel_separation>
      <wheel_radius>0.242</wheel_radius>

      <topic>/model/FLIP/cmd_vel</topic>
      <odom_topic>/model/FLIP/odometry</odom_topic>
      <tf_topic>/model/FLIP/tf</tf_topic>

      <frame_id>odom</frame_id>
      <child_frame_id>chassis</child_frame_id>

      </plugin>

      <!-- Moving Forward-->
      <plugin filename="gz-sim-triggered-publisher-system"
              name="gz::sim::systems::TriggeredPublisher">
          <input type="gz.msgs.Int32" topic="/keyboard/keypress">
              <match field="data">16777235</match>
          </input>
          <output type="gz.msgs.Twist" topic="/model/FLIP/cmd_vel">
              linear: {x: 1.0}, angular: {z: 0.0}
          </output>
      </plugin>

      <!-- Moving Backward-->
      <plugin filename="gz-sim-triggered-publisher-system"
              name="gz::sim::systems::TriggeredPublisher">
          <input type="gz.msgs.Int32" topic="/keyboard/keypress">
              <match field="data">16777237</match>
          </input>
          <output type="gz.msgs.Twist" topic="/model/FLIP/cmd_vel">
              linear: {x: -1.0}, angular: {z: 0.0}
          </output>
      </plugin>

      <!-- Moving left-->
      <plugin filename="gz-sim-triggered-publisher-system"
              name="gz::sim::systems::TriggeredPublisher">
          <input type="gz.msgs.Int32" topic="/keyboard/keypress">
              <match field="data">16777234</match>
          </input>
          <output type="gz.msgs.Twist" topic="/model/FLIP/cmd_vel">
              linear: {x: 0.0}, angular: {z: 1.0}
          </output>
      </plugin>

      <!-- Moving right-->
      <plugin filename="gz-sim-triggered-publisher-system"
              name="gz::sim::systems::TriggeredPublisher">
          <input type="gz.msgs.Int32" topic="/keyboard/keypress">
              <match field="data">16777236</match>
          </input>
          <output type="gz.msgs.Twist" topic="/model/FLIP/cmd_vel">
              linear: {x: 0.0}, angular: {z: -1.0}
          </output>
      </plugin>
    </model>
   


    <!-- Walls -->
    <include>
      <uri>file:///workspace/models/gazebo/obstacles/walls/horizontalWall0_3x12x3_5</uri>
      <name>horizontalWallBig</name>
      <pose>6.1378297805786133 0 1.75 0 0 0</pose>
    </include>

    <include>
      <uri>file:///workspace/models/gazebo/obstacles/walls/horizontalWall0_3x12x3_5</uri>
      <name>verticalWallBig</name>
      <pose>7.2243547037942335e-06 -5.8478302955627441 1.75 0 0 1.5708000357176291</pose>
    </include>

    <include>
      <uri>file:///workspace/models/gazebo/obstacles/walls/horizontalWall0_3x5x3_5</uri>
      <name>horizontalWallSmall</name>
      <pose>-5.8479700088500977 -3.2032356262207031 1.75 0 0 0</pose>
    </include>

    <include>
      <uri>file:///workspace/models/gazebo/obstacles/walls/verticalWall0_3x5x3_5</uri>
      <name>verticalWallSmall</name>
      <pose>-3.2926583290100098 6.3540897369384766 1.75 0 0 1.5707999672671717</pose>
    </include>

    <include>
      <uri>file:///workspace/models/gazebo/obstacles/walls/horizontalWall0_3x12x3_5</uri>
      <name>horizontalWallBig_1</name>
      <pose>6.1292400360107422 11.98643970489502 1.75 0 0 0</pose>
    </include>

    <include>
      <uri>file:///workspace/models/gazebo/obstacles/walls/verticalWall0_3x12x3_5</uri>
      <name>verticalWallBig_1</name>
      <pose>0.00072676839772611856 17.835100173950195 1.75 0 0 1.5707999672671711</pose>
    </include>

    <include>
      <uri>file:///workspace/models/gazebo/obstacles/walls/horizontalWall0_3x12x3_5</uri>
      <name>horizontalWallBig_2</name>
      <pose>-5.8510937690734863 11.696800231933594 1.75 0 0 0</pose>
    </include>

    <include>
      <uri>file:///workspace/models/gazebo/obstacles/walls/horizontalWall0_3x5x3_5</uri>
      <name>horizontalWallSmall_2</name>
      <pose>-5.849639892578125 4.0064177513122559 1.75 0 0 0</pose>
    </include>

    <include>
      <uri>file:///workspace/models/gazebo/obstacles/walls/verticalWall0_3x12x3_5</uri>
      <name>verticalWallBig_2</name>
      <pose>-11.975589752197266 -5.8330597877502441 1.75 0 0 1.5707999672671717</pose>
    </include>

    <include>
      <uri>file:///workspace/models/gazebo/obstacles/walls/horizontalWall0_3x12x3_5</uri>
      <name>horizontalWallBig_3</name>
      <pose>-17.832462310791016 0.27177301049232483 1.75 0 0 0</pose>
    </include>

    <include>
      <uri>file:///workspace/models/gazebo/obstacles/walls/verticalWall0_3x5x3_5</uri>
      <name>verticalWallSmall_2</name>
      <pose>-8.252507209777832 6.3668909072875977 1.75 0 0 1.5707999672671717</pose>
    </include>

    <include>
      <uri>file:///workspace/models/gazebo/obstacles/walls/verticalWall0_3x5x3_5</uri>
      <name>verticalWallSmall_3</name>
      <pose>-15.482864379882812 6.3641500473022452 1.75 0 0 1.5707999672671717</pose>
    </include>

    <include>
      <uri>file:///workspace/models/gazebo/obstacles/walls/horizontalWall0_3x5x3_5</uri>
      <name>horizontalWallSmall_3</name>
      <pose>-17.841299057006836 9.0118703842163086 1.75 0 0 0</pose>
    </include>

    <include>
      <uri>file:///workspace/models/gazebo/obstacles/walls/verticalWall0_3x12x3_5</uri>
      <name>verticalWallBig_3</name>
      <pose>-11.987987518310547 11.363300323486328 1.75 0 0 1.5707999672671717</pose>
    </include>

    <!-- Objects -->
    <include>
      <uri>file:///workspace/models/gazebo/obstacles/shapes/redCube1x1x1</uri>
      <name>redCube</name>
      <pose>-3.6559658050537109 8.7096595764160156 0.5 0 0 0</pose>
    </include>

    <include>
      <uri>file:///workspace/models/gazebo/obstacles/shapes/greenCylinder0_5x1</uri>
      <name>greenCylinder</name>
      <pose>-7.8899140357971191 -3 0.5 0 0 0</pose>
    </include>

    <include>
      <uri>file:///workspace/models/gazebo/obstacles/shapes/blueBox1x2x1</uri>
      <name>blueBox</name>
      <pose>3 15.608985900878906 0.5 0 0 0</pose>
    </include>

    <include>
      <uri>file:///workspace/models/gazebo/obstacles/shapes/yellowBox1_5x1x1_5</uri>
      <name>yellowBox</name>
      <pose>-7.9256100654602051 4.3805632591247559 0.75 0 0 0</pose>
    </include>

    <include>
      <uri>file:///workspace/models/gazebo/obstacles/shapes/pinkBall0_6</uri>
      <name>pinkBall</name>
      <pose>-8.2594108581542969 8.8796701431274414 0.60000002384185791 0 0 0</pose>
    </include>

    <include>
      <uri>file:///workspace/models/gazebo/obstacles/shapes/orangeBox0_8x0_8x0_8</uri>
      <name>orangeBox</name>
      <pose>-5 5 0.40000000000000002 0 0 0</pose>
    </include>

    <include>
    <uri>https://fuel.gazebosim.org/1.0/Natzy/models/Walking person</uri>
    <name>person1</name>
    <pose>-13.2594108581542969 2.8796701431274414 0.00000002384185791 0 0 0</pose>
    </include>

    <include>
    <uri>https://fuel.gazebosim.org/1.0/OpenRobotics/models/TrolleyBedPatient</uri>
    <name>patientBed</name>
    <pose>-2.6559658050537109 14.7096595764160156 0.0 0 0 0</pose>
    </include>

    <include>
    <uri>https://fuel.gazebosim.org/1.0/OpenRobotics/models/PatientWheelChair</uri>
    <name>patientWheelchair</name>
    <pose>-2 0 0.0 0 0 0</pose>
    </include>

    
  </world>
</sdf>