<?xml version="1.0" ?>
<sdf version="1.7">
  <world name="valley_terrain">
    <physics name="default_physics" default="true" type="ode">
      <max_step_size>0.001</max_step_size>
      <real_time_factor>1</real_time_factor>
    </physics>
    <scene>
      <ambient>0.4 0.4 0.4 1</ambient>
      <background>0.53 0.81 0.92 1</background>
      <shadows>true</shadows>
    </scene>
    <light type="directional" name="sun">
      <cast_shadows>true</cast_shadows>
      <pose>0 0 100 0 0 0</pose>
      <diffuse>0.9 0.9 0.9 1</diffuse>
      <specular>0.2 0.2 0.2 1</specular>
      <direction>-0.5 0.1 -0.9</direction>
    </light>

    <!-- ========== TERRAIN ========== -->
    <model name="terrain"><static>true</static><pose>0 0 0 0 0 0</pose>
      <link name="terrain_link">
        <collision name="terrain_col">
          <geometry><mesh><uri>file://DrivableTerrain.stl</uri><scale>1 1 1</scale></mesh></geometry>
          <surface><friction><ode><mu>0.9</mu><mu2>0.9</mu2></ode></friction>
            <contact><ode><min_depth>0.001</min_depth></ode></contact></surface>
        </collision>
        <visual name="terrain_vis">
          <geometry><mesh><uri>file://DrivableTerrain.stl</uri><scale>1 1 1</scale></mesh></geometry>
          <material><ambient>0.35 0.52 0.28 1</ambient><diffuse>0.42 0.62 0.32 1</diffuse>
            <specular>0.05 0.05 0.05 1</specular></material>
        </visual>
      </link>
    </model>

    <!-- ========== CAR ========== -->
<model name='vehicle' canonical_link='chassis'>
   <pose relative_to='world'>0 0 0 0 0 0</pose>
    <plugin
    filename="gz-sim-sensors-system"
    name="gz::sim::systems::Sensors">
    <render_engine>ogre2</render_engine>
    </plugin>
   <plugin
      filename="gz-sim-diff-drive-system"
      name="gz::sim::systems::DiffDrive">
      <left_joint>left_front_wheel_joint</left_joint>
      <left_joint>left_rear_wheel_joint</left_joint>
      <right_joint>right_front_wheel_joint</right_joint>
      <right_joint>right_rear_wheel_joint</right_joint>
      <wheel_separation>2.2</wheel_separation>   <!-- 2.0 body + 2x 0.1 half-wheel-width -->
      <wheel_radius>0.4</wheel_radius>            <!-- 0.8 diameter / 2 -->
      <odom_publish_frequency>1</odom_publish_frequency>
      <topic>cmd_vel</topic>
   </plugin>
   <plugin
      filename="gz-sim-pose-publisher-system"
      name="gz::sim::systems::PosePublisher">
      <publish_link_pose>false</publish_link_pose>
      <publish_collision_pose>false</publish_collision_pose>
      <publish_visual_pose>false</publish_visual_pose>
      <publish_model_pose>true</publish_model_pose>
      <publish_nested_model_pose>false</publish_nested_model_pose>
      <update_frequency>30</update_frequency>
   </plugin>
      <link name='chassis'>
         <sensor name="depth_camera" type="depth_camera">
         <pose>2.25 0 0.5 0 0 0</pose> <!-- position relative to chassis -->

         <always_on>true</always_on>
         <update_rate>30</update_rate>
         <topic>/camera</topic>

         <camera>
            <horizontal_fov>1.047</horizontal_fov>
            <image>
               <width>640</width>
               <height>480</height>
               <format>R8G8B8</format>
            </image>
            <clip>
               <near>0.05</near>
               <far>15.0</far>
            </clip>
            <depth_camera>
               <output>depths</output>
            </depth_camera>
         </camera>
         </sensor>
         <pose relative_to='__model__'>0 0 0.4 0 0 0</pose>
         <inertial>
            <!--inertial properties of the link mass, inertia matix-->
            <mass>1.14395</mass>
            <inertia>
               <ixx>0.095329</ixx>
               <ixy>0</ixy>
               <ixz>0</ixz>
               <iyy>0.381317</iyy>
               <iyz>0</iyz>
               <izz>0.476646</izz>
            </inertia>
         </inertial>
         <visual name='visual'>
            <pose>0 0 0.5 0 0 0</pose>
            <geometry>
               <box>
                  <size>4.5 2.0 1</size>
               </box>
            </geometry>
         </visual>
         <collision name='collision'>
            <pose>0 0 0.5 0 0 0</pose>
            <geometry>
               <box>
                  <size>4.5 2.0 1</size>
               </box>
            </geometry>
         </collision>
         </link>
         <link name='left_front_wheel'>
         <pose relative_to="chassis">1 1.1 0 -1.5707 0 0</pose>
         <inertial>
            <mass>1</mass>
            <inertia>
               <ixx>0.043333</ixx>
               <ixy>0</ixy>
               <ixz>0</ixz>
               <iyy>0.043333</iyy>
               <iyz>0</iyz>
               <izz>0.08</izz>
            </inertia>
         </inertial>
         <visual name='visual'>
            <geometry>
               <cylinder>
                  <radius>0.4</radius>
                  <length>0.2</length>
               </cylinder>
            </geometry>
            <material>
               <ambient>1.0 0.0 0.0 1</ambient>
               <diffuse>1.0 0.0 0.0 1</diffuse>
               <specular>1.0 0.0 0.0 1</specular>
            </material>
         </visual>
         <collision name='collision'>
            <geometry>
               <cylinder>
                  <radius>0.4</radius>
                  <length>0.2</length>
               </cylinder>
            </geometry>
         </collision>
         </link>
         <link name='left_rear_wheel'>
         <pose relative_to="chassis">-1 1.1 0 -1.5707 0 0</pose>
         <inertial>
            <mass>1</mass>
            <inertia>
               <ixx>0.043333</ixx>
               <ixy>0</ixy>
               <ixz>0</ixz>
               <iyy>0.043333</iyy>
               <iyz>0</iyz>
               <izz>0.08</izz>
            </inertia>
         </inertial>
         <visual name='visual'>
            <geometry>
               <cylinder>
                  <radius>0.4</radius>
                  <length>0.2</length>
               </cylinder>
            </geometry>
            <material>
               <ambient>1.0 0.0 0.0 1</ambient>
               <diffuse>1.0 0.0 0.0 1</diffuse>
               <specular>1.0 0.0 0.0 1</specular>
            </material>
         </visual>
         <collision name='collision'>
            <geometry>
               <cylinder>
                  <radius>0.4</radius>
                  <length>0.2</length>
               </cylinder>
            </geometry>
         </collision>
         </link>
         <!--The same as left wheels but with different position-->
         <link name='right_front_wheel'>
         <pose relative_to="chassis">1 -1.1 0 -1.5707 0 0</pose>
         <!--angles are in radian-->
         <inertial>
            <mass>1</mass>
            <inertia>
               <ixx>0.043333</ixx>
               <ixy>0</ixy>
               <ixz>0</ixz>
               <iyy>0.043333</iyy>
               <iyz>0</iyz>
               <izz>0.08</izz>
            </inertia>
         </inertial>
         <visual name='visual'>
            <geometry>
               <cylinder>
                  <radius>0.4</radius>
                  <length>0.2</length>
               </cylinder>
            </geometry>
            <material>
               <ambient>1.0 0.0 0.0 1</ambient>
               <diffuse>1.0 0.0 0.0 1</diffuse>
               <specular>1.0 0.0 0.0 1</specular>
            </material>
         </visual>
         <collision name='collision'>
            <geometry>
               <cylinder>
                  <radius>0.4</radius>
                  <length>0.2</length>
               </cylinder>
            </geometry>
         </collision>
         </link>
         <link name='right_rear_wheel'>
         <pose relative_to="chassis">-1 -1.1 0 -1.5707 0 0</pose>
         <!--angles are in radian-->
         <inertial>
            <mass>1</mass>
            <inertia>
               <ixx>0.043333</ixx>
               <ixy>0</ixy>
               <ixz>0</ixz>
               <iyy>0.043333</iyy>
               <iyz>0</iyz>
               <izz>0.08</izz>
            </inertia>
         </inertial>
         <visual name='visual'>
            <geometry>
               <cylinder>
                  <radius>0.4</radius>
                  <length>0.2</length>
               </cylinder>
            </geometry>
            <material>
               <ambient>1.0 0.0 0.0 1</ambient>
               <diffuse>1.0 0.0 0.0 1</diffuse>
               <specular>1.0 0.0 0.0 1</specular>
            </material>
         </visual>
         <collision name='collision'>
            <geometry>
               <cylinder>
                  <radius>0.4</radius>
                  <length>0.2</length>
               </cylinder>
            </geometry>
         </collision>
         </link>
         <joint name='left_front_wheel_joint' type='revolute'>
            <pose relative_to='left_front_wheel'/>
            <parent>chassis</parent>
            <child>left_front_wheel</child>
            <axis>
               <xyz expressed_in='__model__'>0 1 0</xyz>
               <!--can be defined as any frame or even arbitrary frames-->
               <limit>
                  <lower>-1.79769e+308</lower>
                  <!--negative infinity-->
                  <upper>1.79769e+308</upper>
                  <!--positive infinity-->
               </limit>
            </axis>
         </joint>
         <joint name='left_rear_wheel_joint' type='revolute'>
            <pose relative_to='left_rear_wheel'/>
            <parent>chassis</parent>
            <child>left_rear_wheel</child>
            <axis>
               <xyz expressed_in='__model__'>0 1 0</xyz>
               <!--can be defined as any frame or even arbitrary frames-->
               <limit>
                  <lower>-1.79769e+308</lower>
                  <!--negative infinity-->
                  <upper>1.79769e+308</upper>
                  <!--positive infinity-->
               </limit>
            </axis>
         </joint>
         <joint name='right_front_wheel_joint' type='revolute'>
            <pose relative_to='right_front_wheel'/>
            <parent>chassis</parent>
            <child>right_front_wheel</child>
            <axis>
               <xyz expressed_in='__model__'>0 1 0</xyz>
               <!--can be defined as any frame or even arbitrary frames-->
               <limit>
                  <lower>-1.79769e+308</lower>
                  <!--negative infinity-->
                  <upper>1.79769e+308</upper>
                  <!--positive infinity-->
               </limit>
            </axis>
         </joint>
         <joint name='right_rear_wheel_joint' type='revolute'>
            <pose relative_to='right_rear_wheel'/>
            <parent>chassis</parent>
            <child>right_rear_wheel</child>
            <axis>
               <xyz expressed_in='__model__'>0 1 0</xyz>
               <limit>
                  <lower>-1.79769e+308</lower>
                  <!--negative infinity-->
                  <upper>1.79769e+308</upper>
                  <!--positive infinity-->
               </limit>
            </axis>
         </joint>
      </model>
  </world>
</sdf>