<?xml version="1.0" ?>
<sdf version="1.10">
    <world name="car_world">
        <physics name="1ms" type="ignored">
            <max_step_size>0.001</max_step_size>
            <real_time_factor>1.0</real_time_factor>
        </physics>
        <plugin
            filename="gz-sim-physics-system"
            name="gz::sim::systems::Physics">
        </plugin>
        <plugin
            filename="gz-sim-user-commands-system"
            name="gz::sim::systems::UserCommands">
        </plugin>
        <plugin
            filename="gz-sim-scene-broadcaster-system"
            name="gz::sim::systems::SceneBroadcaster">
        </plugin>

        <plugin filename="gz-sim-imu-system"
                name="gz::sim::systems::Imu">
        </plugin>

        <light type="directional" name="sun">
            <cast_shadows>true</cast_shadows>
            <pose>0 0 10 0 0 0</pose>
            <diffuse>0.8 0.8 0.8 1</diffuse>
            <specular>0.2 0.2 0.2 1</specular>
            <attenuation>
                <range>1000</range>
                <constant>0.9</constant>
                <linear>0.01</linear>
                <quadratic>0.001</quadratic>
            </attenuation>
            <direction>-0.5 0.1 -0.9</direction>
        </light>

        <model name="ground_plane">
            <static>true</static>
            <link name="link">
                <collision name="collision">
                <geometry>
                    <plane>
                    <normal>0 0 1</normal>
                    </plane>
                </geometry>
                </collision>
                <visual name="visual">
                <geometry>
                    <plane>
                    <normal>0 0 1</normal>
                    <size>60 70</size>
                    </plane>
                </geometry>
                <material>
                    <ambient>0.8 0.8 0.8 1</ambient>
                    <diffuse>0.8 0.8 0.8 1</diffuse>
                    <specular>0.8 0.8 0.8 1</specular>
                </material>
                </visual>
            </link>
        </model>
    <model name='vehicle_blue' canonical_link='chassis'>
        <pose relative_to='world'>-3.8 -2 0 0 0 0</pose>

        <link name='chassis'>
            <pose relative_to='__model__'>0.25 0 0.2 0 0 0</pose>
            <inertial>
                <mass>1.14395</mass>
                <inertia>
                    <ixx>0.095329</ixx>
                    <ixy>0</ixy>
                    <ixz>0</ixz>
                    <iyy>0.381317</iyy>
                    <iyz>0</iyz>
                    <izz>0.476646</izz>
                </inertia>
            </inertial>
            <visual name='visual'>
                <geometry>
                    <box>
                        <size>1.0 0.5 0.25</size>
                    </box>
                </geometry>
                <material>
                    <ambient>0.0 0.0 1.0 1</ambient>
                    <diffuse>0.0 0.0 1.0 1</diffuse>
                    <specular>0.0 0.0 1.0 1</specular>
                </material>
            </visual>
            <collision name='collision'>
                <geometry>
                    <box>
                        <size>1.0 0.5 0.25</size>
                    </box>
                </geometry>
            </collision>
        </link>

        <link name='left_wheel'>
            <pose relative_to="chassis">-0.25 0.3 0 -1.5707 0 0</pose>
            <inertial>
                <mass>1</mass>
                <inertia>
                    <ixx>0.043333</ixx>
                    <ixy>0</ixy>
                    <ixz>0</ixz>
                    <iyy>0.043333</iyy>
                    <iyz>0</iyz>
                    <izz>0.08</izz>
                </inertia>
            </inertial>
            <visual name='visual'>
                <geometry>
                    <cylinder>
                        <radius>0.2</radius>
                        <length>0.1</length>
                    </cylinder>
                </geometry>
                <material>
                    <ambient>1.0 0.0 0.0 1</ambient>
                    <diffuse>1.0 0.0 0.0 1</diffuse>
                    <specular>1.0 0.0 0.0 1</specular>
                </material>
            </visual>
            <collision name='collision'>
                <geometry>
                    <cylinder>
                        <radius>0.2</radius>
                        <length>0.1</length>
                    </cylinder>
                </geometry>
            </collision>

            <sensor name="imu_sensor" type="imu">
                <always_on>1</always_on>
                <update_rate>1</update_rate>
                <visualize>true</visualize>
                <topic>imu</topic>
            </sensor>
        </link>

        <link name='right_wheel'>
            <pose relative_to="chassis">-0.25 -0.3 0 -1.5707 0 0</pose>
            <inertial>
                <mass>1</mass>
                <inertia>
                    <ixx>0.043333</ixx>
                    <ixy>0</ixy>
                    <ixz>0</ixz>
                    <iyy>0.043333</iyy>
                    <iyz>0</iyz>
                    <izz>0.08</izz>
                </inertia>
            </inertial>
            <visual name='visual'>
                <geometry>
                    <cylinder>
                        <radius>0.2</radius>
                        <length>0.1</length>
                    </cylinder>
                </geometry>
                <material>
                    <ambient>1.0 0.0 0.0 1</ambient>
                    <diffuse>1.0 0.0 0.0 1</diffuse>
                    <specular>1.0 0.0 0.0 1</specular>
                </material>
            </visual>
            <collision name='collision'>
                <geometry>
                    <cylinder>
                        <radius>0.2</radius>
                        <length>0.1</length>
                    </cylinder>
                </geometry>
            </collision>
        </link>

        <frame name="caster_frame" attached_to='chassis'>
            <pose>0.4 0 -0.1 0 0 0</pose>
        </frame>

        <link name='caster'>
            <pose relative_to='caster_frame'/>
            <inertial>
                <mass>1</mass>
                <inertia>
                    <ixx>0.016</ixx>
                    <ixy>0</ixy>
                    <ixz>0</ixz>
                    <iyy>0.016</iyy>
                    <iyz>0</iyz>
                    <izz>0.016</izz>
                </inertia>
            </inertial>
            <visual name='visual'>
                <geometry>
                    <sphere>
                        <radius>0.1</radius>
                    </sphere>
                </geometry>
                <material>
                    <ambient>0.0 1 0.0 1</ambient>
                    <diffuse>0.0 1 0.0 1</diffuse>
                    <specular>0.0 1 0.0 1</specular>
                </material>
            </visual>
            <collision name='collision'>
                <geometry>
                    <sphere>
                        <radius>0.1</radius>
                    </sphere>
                </geometry>
            </collision>
        </link>

        <joint name='left_wheel_joint' type='revolute'>
            <pose relative_to='left_wheel'/>
            <parent>chassis</parent>
            <child>left_wheel</child>
            <axis>
                <xyz expressed_in='__model__'>0 1 0</xyz>
                <limit>
                    <lower>-1.79769e+308</lower>
                    <upper>1.79769e+308</upper>
                </limit>
            </axis>
        </joint>

        <joint name='right_wheel_joint' type='revolute'>
            <pose relative_to='right_wheel'/>
            <parent>chassis</parent>
            <child>right_wheel</child>
            <axis>
                <xyz expressed_in='__model__'>0 1 0</xyz>
                <limit>
                    <lower>-1.79769e+308</lower>
                    <upper>1.79769e+308</upper>
                </limit>
            </axis>
        </joint>

        <joint name='caster_wheel' type='ball'>
            <parent>chassis</parent>
            <child>caster</child>
        </joint>

        <plugin
            filename="gz-sim-diff-drive-system"
            name="gz::sim::systems::DiffDrive">
            <left_joint>left_wheel_joint</left_joint>
            <right_joint>right_wheel_joint</right_joint>
            <wheel_separation>0.6</wheel_separation>
            <wheel_radius>0.2</wheel_radius>
            <odom_publish_frequency>1</odom_publish_frequency>
            <topic>cmd_vel</topic>
        </plugin>

        <plugin filename="gz-sim-triggered-publisher-system"
                name="gz::sim::systems::TriggeredPublisher">
            <input type="gz.msgs.Int32" topic="/keyboard/keypress">
                <match field="data">16777235</match>
            </input>
            <output type="gz.msgs.Twist" topic="/cmd_vel">
                linear: {x: 0.5}, angular: {z: 0.0}
            </output>
        </plugin>

        <plugin filename="gz-sim-triggered-publisher-system"
                name="gz::sim::systems::TriggeredPublisher">
            <input type="gz.msgs.Int32" topic="/keyboard/keypress">
                <match field="data">16777237</match>
            </input>
            <output type="gz.msgs.Twist" topic="/cmd_vel">
                linear: {x: -0.5}, angular: {z: 0.0}
            </output>
        </plugin>

        <plugin filename="gz-sim-triggered-publisher-system"
                name="gz::sim::systems::TriggeredPublisher">
            <input type="gz.msgs.Int32" topic="/keyboard/keypress">
                <match field="data">16777234</match>
            </input>
            <output type="gz.msgs.Twist" topic="/cmd_vel">
                linear: {x: 0.0}, angular: {z: 0.5}
            </output>
        </plugin>

        <plugin filename="gz-sim-triggered-publisher-system"
                name="gz::sim::systems::TriggeredPublisher">
            <input type="gz.msgs.Int32" topic="/keyboard/keypress">
                <match field="data">16777236</match>
            </input>
            <output type="gz.msgs.Twist" topic="/cmd_vel">
                linear: {x: 0.0}, angular: {z: -0.5}
            </output>
        </plugin>
    </model>


    <include>
        <name>room</name>
        <uri>https://fuel.gazebosim.org/1.0/veer/models/Indoor lightmap</uri>
        <pose relative_to='world'>0 0 0 0 0 0</pose>
    </include>

    <include>
        <name>bedWardrobeChairAndTable</name>
        <uri>https://fuel.gazebosim.org/1.0/GoogleResearch/models/BEDROOM_NEO</uri>
        <scale>10 10 10</scale>
        <pose relative_to='room'>4.25 1.90 0 0 0 0</pose>
    </include>

    <include>
        <name>sofa</name>
        <uri>https://fuel.gazebosim.org/1.0/OpenRobotics/models/Sofa</uri>
        <pose relative_to='room'>4.70 -6.10 0 0 0 1.57</pose>
    </include>

    <include>
        <name>miniSofa</name>
        <uri>
        https://fuel.gazebosim.org/1.0/OpenRobotics/models/MiniSofa
        </uri>
        <pose relative_to='room'>2.7 -6.10 0 0 0 -1.57</pose>
    </include>

    <include>
        <name>standingPerson</name>   
        <scale>0.75 0.75 0.75</scale>
        <uri>
        https://fuel.gazebosim.org/1.0/OpenRobotics/models/Standing person
        </uri>
        <pose relative_to='room'>2 2 0 0 0 -1</pose>
    </include>

    <include>
        <name>sittingKid</name>   
        <scale>0.75 0.75 0.75</scale>
        <uri>
        https://fuel.gazebosim.org/1.0/OpenRobotics/models/VisitorKidSit
        </uri>
        <pose relative_to='room'>3 -6 0 0 0 3.14</pose>
    </include>


    <!-- <include>
        <name>FLIP</name>   
        <scale>0.75 0.75 0.75</scale>
        <uri>
        https://fuel.gazebosim.org/1.0/OpenRobotics/models/MARBLE_HD2_VISUALS_ONLY
        </uri>
        <pose relative_to='room'>3 0 0 0 0 0</pose>
    </include> -->


    <include>
        <name>tv</name>   
        <scale>0.75 0.75 0.75</scale>
        <uri>
        https://fuel.gazebosim.org/1.0/sebbyjp/models/tv_65in_emissive
        </uri>
        <pose relative_to='room'>-1.7 3.10 1.80 0 0 -1.57</pose>
    </include>

    <include>
        <name>patient</name>   
        <uri>
        https://fuel.gazebosim.org/1.0/OpenRobotics/models/PatientWheelChair
        </uri>
        <pose relative_to='room'>-1.80 0.80 0 0 0 1.57</pose>
    </include>


    <include>
        <name>smallVase</name>   
        <uri>
        https://fuel.gazebosim.org/1.0/Cole/models/Sunken Vase 02
        </uri>
        <pose relative_to='room'>-0.8 2.9 0.13 0 0 -1.57</pose>
    </include>

    <include>
        <name>vase</name>   
        <uri>
        https://fuel.gazebosim.org/1.0/Cole/models/Sunken Vase
        </uri>
        <pose relative_to='room'>-3.8 2.8 0.0 0 0 -1.57</pose>
    </include>

    <include>
        <name>doorFrame</name> 
        <uri>
        https://fuel.gazebosim.org/1.0/OpenRobotics/models/DRC Practice: Door debris base
        </uri>
        <pose relative_to='world'>-4.2 -4.2 1.0 1.56 0 -1.56</pose>
    </include>

    <include>
        <name>doorHandle1</name> 
        <uri>
        https://fuel.gazebosim.org/1.0/OpenRobotics/models/Door handle
        </uri>
        <pose relative_to='room'>-4.19 -4.59 1.10 -1.57 0 -1.54</pose>
    </include>

    <include>
        <name>doorHandle2</name> 
        <uri>
        https://fuel.gazebosim.org/1.0/OpenRobotics/models/Door handle
        </uri>
        <pose relative_to='room'>-4.20 -4.59 1.10 1.55 0 -1.55</pose>
    </include>


    </world>
</sdf>